[2023-03-10T08:59:27.381+0000] {taskinstance.py:1083} INFO - Dependencies all met for <TaskInstance: ingest_to_db.etl manual__2023-03-10T08:59:25.849315+00:00 [queued]>
[2023-03-10T08:59:27.405+0000] {taskinstance.py:1083} INFO - Dependencies all met for <TaskInstance: ingest_to_db.etl manual__2023-03-10T08:59:25.849315+00:00 [queued]>
[2023-03-10T08:59:27.406+0000] {taskinstance.py:1279} INFO - 
--------------------------------------------------------------------------------
[2023-03-10T08:59:27.406+0000] {taskinstance.py:1280} INFO - Starting attempt 1 of 3
[2023-03-10T08:59:27.406+0000] {taskinstance.py:1281} INFO - 
--------------------------------------------------------------------------------
[2023-03-10T08:59:27.436+0000] {taskinstance.py:1300} INFO - Executing <Task(PythonOperator): etl> on 2023-03-10 08:59:25.849315+00:00
[2023-03-10T08:59:27.445+0000] {standard_task_runner.py:55} INFO - Started process 289 to run task
[2023-03-10T08:59:27.454+0000] {standard_task_runner.py:82} INFO - Running: ['***', 'tasks', 'run', 'ingest_to_db', 'etl', 'manual__2023-03-10T08:59:25.849315+00:00', '--job-id', '3', '--raw', '--subdir', 'DAGS_FOLDER/ingest_to_db.py', '--cfg-path', '/tmp/tmpb5pz5_1r']
[2023-03-10T08:59:27.458+0000] {standard_task_runner.py:83} INFO - Job 3: Subtask etl
[2023-03-10T08:59:27.568+0000] {task_command.py:388} INFO - Running <TaskInstance: ingest_to_db.etl manual__2023-03-10T08:59:25.849315+00:00 [running]> on host b632355117cc
[2023-03-10T08:59:27.716+0000] {taskinstance.py:1509} INFO - Exporting the following env vars:
AIRFLOW_CTX_DAG_OWNER=***
AIRFLOW_CTX_DAG_ID=ingest_to_db
AIRFLOW_CTX_TASK_ID=etl
AIRFLOW_CTX_EXECUTION_DATE=2023-03-10T08:59:25.849315+00:00
AIRFLOW_CTX_TRY_NUMBER=1
AIRFLOW_CTX_DAG_RUN_ID=manual__2023-03-10T08:59:25.849315+00:00
[2023-03-10T08:59:27.718+0000] {taskinstance.py:1768} ERROR - Task failed with exception
Traceback (most recent call last):
  File "/home/airflow/.local/lib/python3.7/site-packages/airflow/operators/python.py", line 175, in execute
    return_value = self.execute_callable()
  File "/home/airflow/.local/lib/python3.7/site-packages/airflow/operators/python.py", line 192, in execute_callable
    return self.python_callable(*self.op_args, **self.op_kwargs)
  File "/opt/airflow/dags/ingest_to_db.py", line 71, in etl
    data = extract_data(token, 1)
  File "/opt/airflow/dags/ingest_to_db.py", line 23, in extract_data
    yesterday = int((datetime.datetime.now() - datetime.timedelta(days=days)).timestamp()) * 1000
NameError: name 'datetime' is not defined
[2023-03-10T08:59:27.734+0000] {taskinstance.py:1323} INFO - Marking task as UP_FOR_RETRY. dag_id=ingest_to_db, task_id=etl, execution_date=20230310T085925, start_date=20230310T085927, end_date=20230310T085927
[2023-03-10T08:59:27.754+0000] {standard_task_runner.py:105} ERROR - Failed to execute job 3 for task etl (name 'datetime' is not defined; 289)
[2023-03-10T08:59:27.785+0000] {local_task_job.py:208} INFO - Task exited with return code 1
[2023-03-10T08:59:27.814+0000] {taskinstance.py:2578} INFO - 0 downstream tasks scheduled from follow-on schedule check
